Workbook

Sheet СТ-41
A1: ВЕДОМОСТЬ
A2: индивидуальной оценки
A3: старшины 41 курса сержанта Шуплецова Евгения Андреевича
A5: № | B5: Оценка служебной деятельности | C5: Результаты служебной деятельности | D5: Количество баллов
A6: п/п
A7: 1. | B7: Результаты промежуточной аттестации | D7: =IF(IFERROR(SEARCH("подразделения ≥ 4,5", C7), 0) > 0, 5, IF(IFERROR(SEARCH("подразделения ≥ 4,0", C7), 0) > 0, 3, IF(IFERROR(SEARCH("<", C7), 0) > 0, 0,))) | E7: Средний балл подразделения ≥ 4,5 Средний балл старшины курса ≥ 4,0
E8: Средний балл подразделения ≥ 4,0 Средний балл старшины курса ≥ 4,0
E9: Средний балл подразделения < 4,0 Средний балл старшины курса < 4,0
A10: 2. | B10: Наличие академических задолженностей | D10: =IF(C10="В подразделении и у старшины курса отсутствуют академические задолженности",10,IF(C10="Имеются задолженности в подразделении или у старшины курса",0,"")) | E10: В подразделении и у старшины курса отсутствуют академические задолженности
E11: Имеются задолженности в подразделении или у старшины курса
A12: 3. | B12: Наличие текущих задолженностей | D12: =IF(C12="Текущие задолженности в подразделении и у старшины курса отсутствуют",5,IF(C12="Имеются менее 10% задолженностей в подразделении или у старшины курса",3,IF(C12="Имеются более 10% задолженностей в подразделении или у старшины курса",0,""))) | E12: Текущие задолженности в подразделении и у старшины курса отсутствуют
E13: Имеются менее 10% задолженностей в подразделении или у старшины курса
E14: Имеются более 10% задолженностей в подразделении или у старшины курса
A15: 4. | B15: Замечания от УМО, преподавателей и старших начальников в ходе проведения занятий и самостоятельной работы | D15: =IF(C15="Замечаний нет",5,IF(C15="Имеются замечания",0,"")) | E15: Замечаний нет
E16: Имеются замечания
A18: 5. | B18: Наличие ПРО, ПРЕ, грубых дисциплинарных проступков | D18: =IF(C18="ПРО, ПРЕ, ГДП в подразделении и у старшины курса отсутствуют",10,IF(C18="ПРО, ПРЕ отсутствуют, имеются не снятые взыскания за ГДП в подразделении, у старшины курса отсутствуют",2,IF(C18="Совершено ПРО, ПРЕ, ГДП в подразделении или старшины курса или допущено сокрытие",0,""))) | E18: ПРО, ПРЕ, ГДП в подразделении и у старшины курса отсутствуют
E19: ПРО, ПРЕ отсутствуют, имеются не снятые взыскания за ГДП в подразделении, у старшины курса отсутствуют
E20: Совершено ПРО, ПРЕ, ГДП в подразделении или старшины курса или допущено сокрытие
A21: 6. | B21: Дисциплинарная практика | D21: =IF(C21="Дисциплинарная практика к подчиненному личному составу ведется",5,IF(C21="Дисциплинарная практика к подчиненному личному составу не реализуется или старшина курса имеет дисциплинарные взыскания",0,"")) | E21: Дисциплинарная практика к подчиненному личному составу ведется
E22: Дисциплинарная практика к подчиненному личному составу не реализуется или старшина курса имеет дисциплинарные взыскания
A23: 7. | B23: Знание обстановки в подразделении с докладом начальнику факультета (курса) по возможным отклонениям, ведение книжки сержанта | D23: =IF(C23="Обстановкой владеет, доклады представляет, книжка сержантов актуальна",10,IF(C23="Обстановкой владеет, доклады представляет, книжка сержантов не актуальна",5,IF(C23="Обстановкой не владеет, доклады не представляет, книжка сержантов не актуальна",0,""))) | E23: Обстановкой владеет, доклады представляет, книжка сержантов актуальна
E24: Обстановкой владеет, доклады представляет, книжка сержантов не актуальна
E25: Обстановкой не владеет, доклады не представляет, книжка сержантов не актуальна
A26: 8. | B26: Распределение увольнений | D26: =IF(C26="Увольнения между учебными группами распределены равномерно",2,IF(C26="Увольнения между учебными группами распределены не равномерно",0,"")) | E26: Увольнения между учебными группами распределены равномерно
E27: Увольнения между учебными группами распределены не равномерно
A28: 9. | B28: Распределение нарядов, уборщиков по территории и расположению | D28: =IF(C28="Наряды и уборщики распределены равномерно",2,IF(C28="Наряды распределены равномерно, уборщики не равномерно",1,IF(C28="Наряды и уборщики распределены не равномерно",0,""))) | E28: Наряды и уборщики распределены равномерно
E29: Наряды распределены равномерно, уборщики не равномерно
E30: Наряды и уборщики распределены не равномерно
A31: 10. | B31: Организация подготовки суточного наряда назначенного от подразделения | D31: =IF(C31="Подготовка проведена, на разводе замечаний нет",5,IF(C31="Подготовка проведена, на разводе более трех замечаний",3,IF(C31="Подготовка не проведена, на разводе более трех замечаний или личный состав не допущен",0,""))) | E31: Подготовка проведена, на разводе замечаний нет
E32: Подготовка проведена, на разводе более трех замечаний
E33: Подготовка не проведена, на разводе более трех замечаний или личный состав не допущен
A34: 11. | B34: Несение службы наряда, назначенного от подразделения | D34: =IF(C34="Замечаний нет, оценка старшине не ниже «хорошо»",5,IF(C34="Замечаний не более пяти, оценка старшине не ниже «хорошо»",3,IF(C34="Замечаний более пяти или наряд отстранен, оценка старшине ниже «хорошо»",0,""))) | E34: Замечаний нет, оценка старшине не ниже «хорошо»
E35: Замечаний не более пяти, оценка старшине не ниже «хорошо»
E36: Замечаний более пяти или наряд отстранен, оценка старшине ниже «хорошо»
A37: 12. | B37: Соблюдение требований безопасности | D37: =IF(C37="Нарушений ТБ, приведших к травматизму л/с нет",10,IF(C37="Есть нарушения ТБ, приведшие к травматизму л/с",0,"")) | E37: Нарушений ТБ, приведших к травматизму л/с нет
E38: Есть нарушения ТБ, приведшие к травматизму л/с
A39: 13. | B39: Соблюдение элементов распорядка дня | D39: =IF(C39="Элементы распорядка дня соблюдаются",10,IF(C39="Не более пяти нарушений распорядка дня, срывов мероприятий не допущено",5,IF(C39="Более пяти нарушений элементов распорядка дня или мероприятие сорвано",0,""))) | E39: Элементы распорядка дня соблюдаются
E40: Не более пяти нарушений распорядка дня, срывов мероприятий не допущено
E41: Более пяти нарушений элементов распорядка дня или мероприятие сорвано
A42: 14. | B42: Состояние материальных средств (в том числе оружия) | D42: =IF(C42="Материальные средства подразделения в наличии, исправны, обслужены, хранятся правильно",5,IF(C42="Не выполнены предъявляемые критерии",0,"")) | E42: Материальные средства подразделения в наличии, исправны, обслужены, хранятся правильно
...

Sheet ЗКВ-411
A1: ВЕДОМОСТЬ
A2: индивидуальной оценки
A3: заместителя командира взвода 411 учебной группы сержанта Бойцова Владимира Юрьевича
A5: № | B5: Оценка служебной деятельности | C5: Результаты служебной деятельности | D5: Количество баллов
A6: п/п
A7: 1. | B7: Результаты промежуточной аттестации | D7: =IF(IFERROR(SEARCH("подразделения ≥ 4,5", C7), 0) > 0, 5, IF(IFERROR(SEARCH("подразделения ≥ 4,0", C7), 0) > 0, 3, IF(IFERROR(SEARCH("<", C7), 0) > 0, 0,))) | G7: Средний балл подразделения ≥ 4,5 Средний балл ЗКВ ≥ 4,0
G8: Средний балл подразделения ≥ 4,0 Средний балл ЗКВ ≥ 4,0
G9: Средний балл подразделения < 4,0 Средний балл ЗКВ < 4,0
A10: 2. | B10: Наличие академических задолженностей | D10: =IF(C10="Академические задолженности отсутствуют",10,IF(C10="Имеются академические задолженности в учебной группе или у ЗКВ",0,"")) | G10: Академические задолженности отсутствуют
G11: Имеются академические задолженности в учебной группе или у ЗКВ
A12: 3. | B12: Наличие текущих задолженностей | D12: =IF(C12="В подразделении и у ЗКВ отсутствуют текущие задолженности",5,IF(C12="Имеются менее 20% текущих задолженностей в подразделении или у ЗКВ",3,IF(C12="Имеются более 20% текущих задолженностей в подразделении или у ЗКВ",0,""))) | G12: В подразделении и у ЗКВ отсутствуют текущие задолженности
G13: Имеются менее 20% текущих задолженностей в подразделении или у ЗКВ
G14: Имеются более 20% текущих задолженностей в подразделении или у ЗКВ
A15: 4. | B15: Организация учебных занятий | D15: =IF(C15="Подразделение прибыло на занятие своевременно; дежурный по аудитории назначен; ЖУУЗ и классная доска оформлены; литература, конспекты, ПЭВМ (по необходимости) получены; внутренний порядок в аудитории поддерживается",5,IF(C15="Подразделение прибыло на занятие своевременно; дежурный по аудитории назначен; литература, конспекты, ПЭВМ (по необходимости) получены; ЖУУЗ или классная доска оформлены не своевременно; или имеются отклонения по внутреннему порядку в аудитории",3,IF(C15="Подразделение опоздало на занятие; или ЖУУЗ и классная доска не оформлены; литература, конспекты, ПЭВМ (по необходимости) не получены; или внутренний порядок в аудитории не поддерживается",0,""))) | L15: Подразделение прибыло на занятие своевременно; дежурный по аудитории назначен; ЖУУЗ и классная доска оформлены; литература, конспекты, ПЭВМ (по необходимости) получены; внутренний порядок в аудитории поддерживается
L16: Подразделение прибыло на занятие своевременно; дежурный по аудитории назначен; литература, конспекты, ПЭВМ (по необходимости) получены; ЖУУЗ или классная доска оформлены не своевременно; или имеются отклонения по внутреннему порядку в аудитории
L17: Подразделение опоздало на занятие; или ЖУУЗ и классная доска не оформлены; литература, конспекты, ПЭВМ (по необходимости) не получены; или внутренний порядок в аудитории не поддерживается
A18: 5. | B18: Организация самостоятельной работы | D18: =IF(IFERROR(SEARCH("30%", C18), 0) > 0, 5, IF(IFERROR(SEARCH("10%", C18), 0) > 0, 3, IF(IFERROR(SEARCH("не получены", C18), 0) > 0, 0,))) | L18: Подразделение прибыло на СР своевременно; дежурный по аудитории назначен; ЖУУЗ и классная доска оформлены; внутренний порядок в аудитории поддерживается; литература, ПЭВМ (не менее 30%) получены; журнал ЗКВ, план СР оформлены и выполняются; перерывы организованы
L19: Подразделение прибыло на СР своевременно; дежурный по аудитории назначен; ЖУУЗ или классная доска заполнены не своевременно; имеются отклонения по внутреннему порядку в аудитории; ПЭВМ (не менее 10%) получены; литература получена в недостаточном количестве; журнал ЗКВ, план СР оформлены не в полном объеме или не выполняется; перерывы организованы
L20: Подразделение опоздала на СР; или дежурный по аудитории не назначен; или ЖУУЗ и классная доска не оформлены; или внутренний порядок в аудитории не поддерживается; или литература, ПЭВМ не получены; или журнал ЗКВ, план СР не оформлены и не выполняются; или личный состав спит; или перерывы не организованы
A21: 6. | B21: Замечания от УМО, преподавателей и старших начальников в ходе проведения занятий и самостоятельной работы | D21: =IF(C21="Замечания в подразделении и у ЗКВ отсутствуют",5,IF(C21="В подразделении 2 замечания у ЗКВ отсутствуют",3,IF(C21="В подразделении 3 и более замечаний или замечания у ЗКВ",0,""))) | G21: Замечания в подразделении и у ЗКВ отсутствуют
G22: В подразделении 2 замечания у ЗКВ отсутствуют
G23: В подразделении 3 и более замечаний или замечания у ЗКВ
A24: 7. | B24: Наличие ПРО, ПРЕ, грубых дисциплинарных проступков | D24: =IF(C24="ПРО, ПРЕ, ГДП в подразделении и ЗКВ отсутствуют",10,IF(C24="ПРО, ПРЕ отсутствуют, имеются не снятые взыскания за ГДП в подразделении, у ЗКВ отсутствуют",2,IF(C24="Совершено ПРО, ПРЕ, ГДП в подразделении или ЗКВ или допущено сокрытие",0,""))) | G24: ПРО, ПРЕ, ГДП в подразделении и ЗКВ отсутствуют
G25: ПРО, ПРЕ отсутствуют, имеются не снятые взыскания за ГДП в подразделении, у ЗКВ отсутствуют
G26: Совершено ПРО, ПРЕ, ГДП в подразделении или ЗКВ или допущено сокрытие
A27: 8. | B27: Дисциплинарная практика | D27: =IF(C27="Дисциплинарная практика к подчиненному личному составу ведется",5,IF(C27="Дисциплинарная практика к подчиненному личному составу не реализуется или ЗКВ имеет дисциплинарные взыскания",0,"")) | G27: Дисциплинарная практика к подчиненному личному составу ведется
G28: Дисциплинарная практика к подчиненному личному составу не реализуется или ЗКВ имеет дисциплинарные взыскания
A29: 9. | B29: Знание обстановки в подразделении с докладом начальнику факультета (курса) по возможным отклонениям, ведение книжки сержанта | D29: =IF(C29="Обстановкой владеет, доклады представляет, книжка сержантов актуальна",10,IF(C29="Обстановкой владеет, доклады представляет, книжка сержантов не актуальна",5,IF(C29="Обстановкой не владеет, доклады не представляет, книжка сержантов не актуальна",0,""))) | G29: Обстановкой владеет, доклады представляет, книжка сержантов актуальна
G30: Обстановкой владеет, доклады представляет, книжка сержантов не актуальна
G31: Обстановкой не владеет, доклады не представляет, книжка сержантов не актуальна
A32: 10. | B32: Подведение итогов в подразделении | D32: =IF(C32="Подведение итогов актуально, поставлены конкретные задачи и проводится в установленное время",3,IF(C32="Подведение итогов не актуально, не поставлены задачи или не проводится",0,"")) | G32: Подведение итогов актуально, поставлены конкретные задачи и проводится в установленное время
G33: Подведение итогов не актуально, не поставлены задачи или не проводится
A34: 11. | B34: Распределение увольнений | D34: =IF(C34="Увольнения распределены равномерно",2,IF(C34="Увольнения распределяются не равномерно",0,"")) | G34: Увольнения распределены равномерно
G35: Увольнения распределяются не равномерно
A36: 12. | B36: Распределение нарядов, уборщиков по территории и расположению | D36: =IF(C36="Наряды и уборщики распределены равномерно",2,IF(C36="Наряды распределены равномерно, уборщики не равномерно",1,IF(C36="Наряды и уборщики распределены не равномерно",0,""))) | G36: Наряды и уборщики распределены равномерно
G37: Наряды распределены равномерно, уборщики не равномерно
G38: Наряды и уборщики распределены не равномерно
A39: 13. | B39: Несение службы наряда, назначенного от подразделения | D39: =IF(C39="Замечания у подчиненного л/с отсутствуют, ЗКВ оценен не ниже «хорошо»",5,IF(C39="Выявлено не более 2 замечаний у подчиненного л/с, ЗКВ оценен не ниже «хорошо»",3,IF(C39="Л/с отстранен или выявлено более 2 замечаний, ЗКВ оценен ниже «хорошо»",0,""))) | G39: Замечания у подчиненного л/с отсутствуют, ЗКВ оценен не ниже «хорошо»
G40: Выявлено не более 2 замечаний у подчиненного л/с, ЗКВ оценен не ниже «хорошо»
G41: Л/с отстранен или выявлено более 2 замечаний, ЗКВ оценен ниже «хорошо»
...

Sheet КО1-411
A1: ВЕДОМОСТЬ
A2: индивидуальной оценки
A3: командира 1-ого отделения 411 учебной группы сержанта Романова Дмитрия Вячеславовича
A5: № | B5: Оценка служебной деятельности | C5: Результаты служебной деятельности | D5: Количество баллов
A6: п/п
A7: 1. | B7: Результаты промежуточной аттестации | C7: Средний балл подразделения ≥ 4,0 Средний балл командира отделения ≥ 4,0 | D7: =IF(IFERROR(SEARCH("подразделения ≥ 4,5", C7), 0) > 0, 5, IF(IFERROR(SEARCH("подразделения ≥ 4,0", C7), 0) > 0, 3, IF(IFERROR(SEARCH("<", C7), 0) > 0, 0,))) | F7: 5 | G7: Средний балл подразделения ≥ 4,5 Средний балл командира отделения ≥ 4,0
F8: 3 | G8: Средний балл подразделения ≥ 4,0 Средний балл командира отделения ≥ 4,0
F9: 0 | G9: Средний балл подразделения < 4,0 Средний балл командира отделения < 4,0
A10: 2. | B10: Наличие академических задолженностей | C10: Академические задолженности в подразделении и у командира учебной группы отсутствуют | D10: =IF(IFERROR(SEARCH("отсутствуют", C10), 0) > 0, 10, IF(IFERROR(SEARCH("имеются", C10), 0) > 0, 0, )) | F10: 10 | G10: Академические задолженности в подразделении и у командира учебной группы отсутствуют
F11: 0 | G11: Академические задолженности в подразделении или у командира учебной группы имеются
A12: 3. | B12: Наличие текущих задолженностей | C12: Текущие задолженности в подразделении и у командира учебной группы отсутствуют | D12: =IF(IFERROR(SEARCH("Текущие задолженности в подразделении и у командира учебной группы отсутствуют", C12), 0) > 0, 5, IF(IFERROR(SEARCH("менее 20%", C12), 0) > 0, 3, IF(IFERROR(SEARCH("более 20%", C12), 0) > 0, 0,))) | F12: 5 | G12: Текущие задолженности в подразделении и у командира учебной группы отсутствуют
F13: 3 | G13: Текущие задолженности в подразделении менее 20% и у командира учебной группы отсутствуют
F14: 0 | G14: Текущие задолженности в подразделении более 20% или имеется у командира учебной группы
A15: 4. | B15: Замечания от УМО, преподавателей и старших начальников в ходе проведения занятий и самостоятельной работы | C15: Наличие одного замечания в подразделении и отсутствует у командира отделения | D15: =IF(IFERROR(SEARCH("Отсутствуют", C15), 0) > 0, 5, IF(IFERROR(SEARCH("Наличие одного", C15), 0) > 0, 3, IF(IFERROR(SEARCH("Наличие двух", C15), 0) > 0, 0,))) | F15: 5 | G15: Отсутствуют замечания в подразделении или у командира отделения
F16: 3 | G16: Наличие одного замечания в подразделении и отсутствует у командира отделения
F17: 0 | G17: Наличие двух и более замечаний в подразделении или у командира отделения
A18: 5. | B18: Наличие ПРО, ПРЕ, грубых дисциплинарных проступков | C18: ПРО, ПРЕ, ГДП в подразделении и у командира отделения отсутствуют | D18: =IF(IFERROR(SEARCH("ПРО, ПРЕ, ГДП в подразделении и у командира отделения отсутствуют", C18), 0) > 0, 10, IF(IFERROR(SEARCH("имеются не снятые взыскания ", C18), 0) > 0, 2, IF(IFERROR(SEARCH("допущено сокрытие", C18), 0) > 0, 0,))) | F18: 10 | G18: ПРО, ПРЕ, ГДП в подразделении и у командира отделения отсутствуют
F19: 2 | G19: ПРО, ПРЕ отсутствуют, имеются не снятые взыскания за ГДП в подразделении, у командира отделения отсутствуют
F20: 0 | G20: Совершено ПРО, ПРЕ, ГДП в подразделении или командиром отделения, или допущено сокрытие
A21: 6. | B21: Дисциплинарная практика | C21: Реализует дисциплинарную практику к подчинённому личному составу и не имеет дисциплинарных взысканий | D21: =IF(IFERROR(SEARCH("Реализует дисциплинарную практику к подчинённому личному составу и не имеет дисциплинарных взысканий", C21), 0) > 0, 5, IF(IFERROR(SEARCH("Не реализует ", C21), 0) > 0, 0, )) | F21: 5 | G21: Реализует дисциплинарную практику к подчинённому личному составу и не имеет дисциплинарных взысканий
F22: 0 | G22: Не реализует дисциплинарную практику к подчинённому личному составу или имеет дисциплинарные взыскания
A23: 7. | B23: Знание обстановки в подразделении с докладом начальнику факультета (курса) по возможным отклонениям, ведение книжки сержанта | C23: Обстановку в подразделении знает и докладывает НФ (НК), информация в книжке сержанта актуальная | D23: =IF(IFERROR(SEARCH("сержанта актуальная", C23), 0) > 0, 10, IF(IFERROR(SEARCH("информация в книжке сержанта не актуальная", C23), 0) > 0, 5, IF(IFERROR(SEARCH("не представлен; и информация в книжке сержанта не актуальная", C23), 0) > 0, 0,))) | F23: 10 | G23: Обстановку в подразделении знает и докладывает НФ (НК), информация в книжке сержанта актуальная
F24: 5 | G24: Обстановку в подразделении знает и докладывает НФ (НК), информация в книжке сержанта не актуальная
F25: 0 | G25: Обстановкой в подразделении не владеет, или доклад НФ (НК) не представлен; и информация в книжке сержанта не актуальная
A26: 8. | B26: Подведение итогов в подразделении | C26: Подведение итогов в подразделении актуально, поставлены конкретные задачи и проводится в установленное время | D26: =IF(IFERROR(SEARCH("Подведение итогов в подразделении актуально", C26), 0) > 0, 3, IF(IFERROR(SEARCH("Подведение итогов в подразделении не актуально ", C26), 0) > 0, 0, )) | F26: 3 | G26: Подведение итогов в подразделении актуально, поставлены конкретные задачи и проводится в установленное время
F27: 0 | G27: Подведение итогов в подразделении не актуально, не поставлены задачи или не проводится
A28: 9. | B28: Несение службы наряда, назначенного от подразделения | C28: Отсутствуют замечания у личного состава наряда, назначенного от подразделения, командир отделения за качество несения службы оценен не ниже «хорошо» | D28: =IF(IFERROR(SEARCH("Отсутствуют замечания ", C28), 0) > 0, 5, IF(IFERROR(SEARCH("Выявлено не более одного замечания ", C28), 0) > 0, 3, IF(IFERROR(SEARCH("Отстранен от несения службы ", C28), 0) > 0, 0,))) | F28: 5 | G28: Отсутствуют замечания у личного состава наряда, назначенного от подразделения, командир отделения за качество несения службы оценен не ниже «хорошо»
F29: 3 | G29: Выявлено не более одного замечания у личного состава наряда, назначенного от подразделения, командир отделения за качество несения службы оценен не ниже «хорошо»
F30: 0 | G30: Отстранен от несения службы или выявлено более одного замечания у личного состава наряда, назначенного от подразделения, или командир отделения за качество несения службы оценен ниже «хорошо»
A31: 10. | B31: Соблюдение требований безопасности | C31: Отсутствуют нарушения ТБ, которые привели к травматизму личного состава в подразделении | D31: =IF(IFERROR(SEARCH("Отсутствуют нарушения ТБ", C31), 0) > 0, 10, IF(IFERROR(SEARCH("Имелись нарушения ТБ", C31), 0) > 0, 0, )) | F31: 10 | G31: Отсутствуют нарушения ТБ, которые привели к травматизму личного состава в подразделении
F32: 0 | G32: Имелись нарушения ТБ, которые привели к травматизму личного состава в подразделении
A33: 11. | B33: Соблюдение элементов распорядка дня | C33: Элементы распорядка дня соблюдаются | D33: =IF(IFERROR(SEARCH("Элементы распорядка дня соблюдаются", C33), 0) > 0, 10, IF(IFERROR(SEARCH("Допущено не более трех", C33), 0) > 0, 5, IF(IFERROR(SEARCH("Допущено более трёх нарушений ", C33), 0) > 0, 0,))) | F33: 10 | G33: Элементы распорядка дня соблюдаются
F34: 5 | G34: Допущено не более трех нарушений элементов распорядка дня, которые не привели к срыву мероприятия в целом
F35: 0 | G35: Допущено более трёх нарушений элементов распорядка дня, которые не привели к срыву мероприятия в целом, или допущен срыв, или нарушение командиром отделения
A36: 12. | B36: Состояние материальных средств (в том числе оружия) | C36: Материальные средства подразделения в наличии, исправны, обслужены, хранятся правильно | D36: =IF(IFERROR(SEARCH("Материальные средства ", C36), 0) > 0, 5, IF(IFERROR(SEARCH("Не выполнены ", C36), 0) > 0, 0, )) | F36: 5 | G36: Материальные средства подразделения в наличии, исправны, обслужены, хранятся правильно
F37: 0 | G37: Не выполнены критерии
A38: 13. | B38: Успеваемость по физической подготовке (культуре) командира отделения (по итогам промежуточной аттестации) | C38: Оценка по физической подготовке (культуре) 5 | D38: =IF(IFERROR(SEARCH("5", C38), 0) > 0, 2, IF(IFERROR(SEARCH("4", C38), 0) > 0, 1, )) | F38: 2 | G38: Оценка по физической подготовке (культуре) 5
F39: 1 | G39: Оценка по физической подготовке (культуре) 4
A40: Итоговая сумма баллов: | D40: =SUM(D7:D39)
A43: Начальник курса
...

Sheet КО2-411
A1: ВЕДОМОСТЬ
A2: индивидуальной оценки
A3: командира 2-ого отделения 411 учебной группы ефрейтора Шахова Вадима Владимировича
A5: № | B5: Оценка служебной деятельности | C5: Результаты служебной деятельности | D5: Количество баллов
A6: п/п
A7: 1. | B7: Результаты промежуточной аттестации | C7: Средний балл подразделения ≥ 4,0 Средний балл командира отделения ≥ 4,0 | D7: =IF(IFERROR(SEARCH("подразделения ≥ 4,5", C7), 0) > 0, 5, IF(IFERROR(SEARCH("подразделения ≥ 4,0", C7), 0) > 0, 3, IF(IFERROR(SEARCH("<", C7), 0) > 0, 0,))) | F7: 5 | G7: Средний балл подразделения ≥ 4,5 Средний балл командира отделения ≥ 4,0
F8: 3 | G8: Средний балл подразделения ≥ 4,0 Средний балл командира отделения ≥ 4,0
F9: 0 | G9: Средний балл подразделения < 4,0 Средний балл командира отделения < 4,0
A10: 2. | B10: Наличие академических задолженностей | C10: Академические задолженности в подразделении и у командира учебной группы отсутствуют | D10: =IF(IFERROR(SEARCH("отсутствуют", C10), 0) > 0, 10, IF(IFERROR(SEARCH("имеются", C10), 0) > 0, 0, )) | F10: 10 | G10: Академические задолженности в подразделении и у командира учебной группы отсутствуют
F11: 0 | G11: Академические задолженности в подразделении или у командира учебной группы имеются
A12: 3. | B12: Наличие текущих задолженностей | C12: Текущие задолженности в подразделении и у командира учебной группы отсутствуют | D12: =IF(IFERROR(SEARCH("Текущие задолженности в подразделении и у командира учебной группы отсутствуют", C12), 0) > 0, 5, IF(IFERROR(SEARCH("менее 20%", C12), 0) > 0, 3, IF(IFERROR(SEARCH("более 20%", C12), 0) > 0, 0,))) | F12: 5 | G12: Текущие задолженности в подразделении и у командира учебной группы отсутствуют
F13: 3 | G13: Текущие задолженности в подразделении менее 20% и у командира учебной группы отсутствуют
F14: 0 | G14: Текущие задолженности в подразделении более 20% или имеется у командира учебной группы
A15: 4. | B15: Замечания от УМО, преподавателей и старших начальников в ходе проведения занятий и самостоятельной работы | C15: Наличие одного замечания в подразделении и отсутствует у командира отделения | D15: =IF(IFERROR(SEARCH("Отсутствуют", C15), 0) > 0, 5, IF(IFERROR(SEARCH("Наличие одного", C15), 0) > 0, 3, IF(IFERROR(SEARCH("Наличие двух", C15), 0) > 0, 0,))) | F15: 5 | G15: Отсутствуют замечания в подразделении или у командира отделения
F16: 3 | G16: Наличие одного замечания в подразделении и отсутствует у командира отделения
F17: 0 | G17: Наличие двух и более замечаний в подразделении или у командира отделения
A18: 5. | B18: Наличие ПРО, ПРЕ, грубых дисциплинарных проступков | C18: ПРО, ПРЕ, ГДП в подразделении и у командира отделения отсутствуют | D18: =IF(IFERROR(SEARCH("ПРО, ПРЕ, ГДП в подразделении и у командира отделения отсутствуют", C18), 0) > 0, 10, IF(IFERROR(SEARCH("имеются не снятые взыскания ", C18), 0) > 0, 2, IF(IFERROR(SEARCH("допущено сокрытие", C18), 0) > 0, 0,))) | F18: 10 | G18: ПРО, ПРЕ, ГДП в подразделении и у командира отделения отсутствуют
F19: 2 | G19: ПРО, ПРЕ отсутствуют, имеются не снятые взыскания за ГДП в подразделении, у командира отделения отсутствуют
F20: 0 | G20: Совершено ПРО, ПРЕ, ГДП в подразделении или командиром отделения, или допущено сокрытие
A21: 6. | B21: Дисциплинарная практика | C21: Реализует дисциплинарную практику к подчинённому личному составу и не имеет дисциплинарных взысканий | D21: =IF(IFERROR(SEARCH("Реализует дисциплинарную практику к подчинённому личному составу и не имеет дисциплинарных взысканий", C21), 0) > 0, 5, IF(IFERROR(SEARCH("Не реализует ", C21), 0) > 0, 0, )) | F21: 5 | G21: Реализует дисциплинарную практику к подчинённому личному составу и не имеет дисциплинарных взысканий
F22: 0 | G22: Не реализует дисциплинарную практику к подчинённому личному составу или имеет дисциплинарные взыскания
A23: 7. | B23: Знание обстановки в подразделении с докладом начальнику факультета (курса) по возможным отклонениям, ведение книжки сержанта | C23: Обстановку в подразделении знает и докладывает НФ (НК), информация в книжке сержанта актуальная | D23: =IF(IFERROR(SEARCH("сержанта актуальная", C23), 0) > 0, 10, IF(IFERROR(SEARCH("информация в книжке сержанта не актуальная", C23), 0) > 0, 5, IF(IFERROR(SEARCH("не представлен; и информация в книжке сержанта не актуальная", C23), 0) > 0, 0,))) | F23: 10 | G23: Обстановку в подразделении знает и докладывает НФ (НК), информация в книжке сержанта актуальная
F24: 5 | G24: Обстановку в подразделении знает и докладывает НФ (НК), информация в книжке сержанта не актуальная
F25: 0 | G25: Обстановкой в подразделении не владеет, или доклад НФ (НК) не представлен; и информация в книжке сержанта не актуальная
A26: 8. | B26: Подведение итогов в подразделении | C26: Подведение итогов в подразделении актуально, поставлены конкретные задачи и проводится в установленное время | D26: =IF(IFERROR(SEARCH("Подведение итогов в подразделении актуально", C26), 0) > 0, 3, IF(IFERROR(SEARCH("Подведение итогов в подразделении не актуально ", C26), 0) > 0, 0, )) | F26: 3 | G26: Подведение итогов в подразделении актуально, поставлены конкретные задачи и проводится в установленное время
F27: 0 | G27: Подведение итогов в подразделении не актуально, не поставлены задачи или не проводится
A28: 9. | B28: Несение службы наряда, назначенного от подразделения | C28: Отсутствуют замечания у личного состава наряда, назначенного от подразделения, командир отделения за качество несения службы оценен не ниже «хорошо» | D28: =IF(IFERROR(SEARCH("Отсутствуют замечания ", C28), 0) > 0, 5, IF(IFERROR(SEARCH("Выявлено не более одного замечания ", C28), 0) > 0, 3, IF(IFERROR(SEARCH("Отстранен от несения службы ", C28), 0) > 0, 0,))) | F28: 5 | G28: Отсутствуют замечания у личного состава наряда, назначенного от подразделения, командир отделения за качество несения службы оценен не ниже «хорошо»
F29: 3 | G29: Выявлено не более одного замечания у личного состава наряда, назначенного от подразделения, командир отделения за качество несения службы оценен не ниже «хорошо»
F30: 0 | G30: Отстранен от несения службы или выявлено более одного замечания у личного состава наряда, назначенного от подразделения, или командир отделения за качество несения службы оценен ниже «хорошо»
A31: 10. | B31: Соблюдение требований безопасности | C31: Отсутствуют нарушения ТБ, которые привели к травматизму личного состава в подразделении | D31: =IF(IFERROR(SEARCH("Отсутствуют нарушения ТБ", C31), 0) > 0, 10, IF(IFERROR(SEARCH("Имелись нарушения ТБ", C31), 0) > 0, 0, )) | F31: 10 | G31: Отсутствуют нарушения ТБ, которые привели к травматизму личного состава в подразделении
F32: 0 | G32: Имелись нарушения ТБ, которые привели к травматизму личного состава в подразделении
A33: 11. | B33: Соблюдение элементов распорядка дня | C33: Элементы распорядка дня соблюдаются | D33: =IF(IFERROR(SEARCH("Элементы распорядка дня соблюдаются", C33), 0) > 0, 10, IF(IFERROR(SEARCH("Допущено не более трех", C33), 0) > 0, 5, IF(IFERROR(SEARCH("Допущено более трёх нарушений ", C33), 0) > 0, 0,))) | F33: 10 | G33: Элементы распорядка дня соблюдаются
F34: 5 | G34: Допущено не более трех нарушений элементов распорядка дня, которые не привели к срыву мероприятия в целом
F35: 0 | G35: Допущено более трёх нарушений элементов распорядка дня, которые не привели к срыву мероприятия в целом, или допущен срыв, или нарушение командиром отделения
A36: 12. | B36: Состояние материальных средств (в том числе оружия) | C36: Материальные средства подразделения в наличии, исправны, обслужены, хранятся правильно | D36: =IF(IFERROR(SEARCH("Материальные средства ", C36), 0) > 0, 5, IF(IFERROR(SEARCH("Не выполнены ", C36), 0) > 0, 0, )) | F36: 5 | G36: Материальные средства подразделения в наличии, исправны, обслужены, хранятся правильно
F37: 0 | G37: Не выполнены критерии
A38: 13. | B38: Успеваемость по физической подготовке (культуре) командира отделения (по итогам промежуточной аттестации) | C38: Оценка по физической подготовке (культуре) 5 | D38: =IF(IFERROR(SEARCH("5", C38), 0) > 0, 2, IF(IFERROR(SEARCH("4", C38), 0) > 0, 1, )) | F38: 2 | G38: Оценка по физической подготовке (культуре) 5
F39: 1 | G39: Оценка по физической подготовке (культуре) 4
A40: Итоговая сумма баллов: | D40: =SUM(D7:D39)
A43: Начальник курса
...

Sheet КО3-411
A1: ВЕДОМОСТЬ
A2: индивидуальной оценки
A3: командира 3-ого отделения 411 учебной группы рядового Тимофеева Дмитрия Александровича
A5: № | B5: Оценка служебной деятельности | C5: Результаты служебной деятельности | D5: Количество баллов
A6: п/п
A7: 1. | B7: Результаты промежуточной аттестации | C7: Средний балл подразделения ≥ 4,0 Средний балл командира отделения ≥ 4,0 | D7: =IF(IFERROR(SEARCH("подразделения ≥ 4,5", C7), 0) > 0, 5, IF(IFERROR(SEARCH("подразделения ≥ 4,0", C7), 0) > 0, 3, IF(IFERROR(SEARCH("<", C7), 0) > 0, 0,))) | F7: 5 | G7: Средний балл подразделения ≥ 4,5 Средний балл командира отделения ≥ 4,0
F8: 3 | G8: Средний балл подразделения ≥ 4,0 Средний балл командира отделения ≥ 4,0
F9: 0 | G9: Средний балл подразделения < 4,0 Средний балл командира отделения < 4,0
A10: 2. | B10: Наличие академических задолженностей | C10: Академические задолженности в подразделении и у командира учебной группы отсутствуют | D10: =IF(IFERROR(SEARCH("отсутствуют", C10), 0) > 0, 10, IF(IFERROR(SEARCH("имеются", C10), 0) > 0, 0, )) | F10: 10 | G10: Академические задолженности в подразделении и у командира учебной группы отсутствуют
F11: 0 | G11: Академические задолженности в подразделении или у командира учебной группы имеются
A12: 3. | B12: Наличие текущих задолженностей | C12: Текущие задолженности в подразделении и у командира учебной группы отсутствуют | D12: =IF(IFERROR(SEARCH("Текущие задолженности в подразделении и у командира учебной группы отсутствуют", C12), 0) > 0, 5, IF(IFERROR(SEARCH("менее 20%", C12), 0) > 0, 3, IF(IFERROR(SEARCH("более 20%", C12), 0) > 0, 0,))) | F12: 5 | G12: Текущие задолженности в подразделении и у командира учебной группы отсутствуют
F13: 3 | G13: Текущие задолженности в подразделении менее 20% и у командира учебной группы отсутствуют
F14: 0 | G14: Текущие задолженности в подразделении более 20% или имеется у командира учебной группы
A15: 4. | B15: Замечания от УМО, преподавателей и старших начальников в ходе проведения занятий и самостоятельной работы | C15: Наличие одного замечания в подразделении и отсутствует у командира отделения | D15: =IF(IFERROR(SEARCH("Отсутствуют", C15), 0) > 0, 5, IF(IFERROR(SEARCH("Наличие одного", C15), 0) > 0, 3, IF(IFERROR(SEARCH("Наличие двух", C15), 0) > 0, 0,))) | F15: 5 | G15: Отсутствуют замечания в подразделении или у командира отделения
F16: 3 | G16: Наличие одного замечания в подразделении и отсутствует у командира отделения
F17: 0 | G17: Наличие двух и более замечаний в подразделении или у командира отделения
A18: 5. | B18: Наличие ПРО, ПРЕ, грубых дисциплинарных проступков | C18: ПРО, ПРЕ, ГДП в подразделении и у командира отделения отсутствуют | D18: =IF(IFERROR(SEARCH("ПРО, ПРЕ, ГДП в подразделении и у командира отделения отсутствуют", C18), 0) > 0, 10, IF(IFERROR(SEARCH("имеются не снятые взыскания ", C18), 0) > 0, 2, IF(IFERROR(SEARCH("допущено сокрытие", C18), 0) > 0, 0,))) | F18: 10 | G18: ПРО, ПРЕ, ГДП в подразделении и у командира отделения отсутствуют
F19: 2 | G19: ПРО, ПРЕ отсутствуют, имеются не снятые взыскания за ГДП в подразделении, у командира отделения отсутствуют
F20: 0 | G20: Совершено ПРО, ПРЕ, ГДП в подразделении или командиром отделения, или допущено сокрытие
A21: 6. | B21: Дисциплинарная практика | C21: Реализует дисциплинарную практику к подчинённому личному составу и не имеет дисциплинарных взысканий | D21: =IF(IFERROR(SEARCH("Реализует дисциплинарную практику к подчинённому личному составу и не имеет дисциплинарных взысканий", C21), 0) > 0, 5, IF(IFERROR(SEARCH("Не реализует ", C21), 0) > 0, 0, )) | F21: 5 | G21: Реализует дисциплинарную практику к подчинённому личному составу и не имеет дисциплинарных взысканий
F22: 0 | G22: Не реализует дисциплинарную практику к подчинённому личному составу или имеет дисциплинарные взыскания
A23: 7. | B23: Знание обстановки в подразделении с докладом начальнику факультета (курса) по возможным отклонениям, ведение книжки сержанта | C23: Обстановку в подразделении знает и докладывает НФ (НК), информация в книжке сержанта актуальная | D23: =IF(IFERROR(SEARCH("сержанта актуальная", C23), 0) > 0, 10, IF(IFERROR(SEARCH("информация в книжке сержанта не актуальная", C23), 0) > 0, 5, IF(IFERROR(SEARCH("не представлен; и информация в книжке сержанта не актуальная", C23), 0) > 0, 0,))) | F23: 10 | G23: Обстановку в подразделении знает и докладывает НФ (НК), информация в книжке сержанта актуальная
F24: 5 | G24: Обстановку в подразделении знает и докладывает НФ (НК), информация в книжке сержанта не актуальная
F25: 0 | G25: Обстановкой в подразделении не владеет, или доклад НФ (НК) не представлен; и информация в книжке сержанта не актуальная
A26: 8. | B26: Подведение итогов в подразделении | C26: Подведение итогов в подразделении актуально, поставлены конкретные задачи и проводится в установленное время | D26: =IF(IFERROR(SEARCH("Подведение итогов в подразделении актуально", C26), 0) > 0, 3, IF(IFERROR(SEARCH("Подведение итогов в подразделении не актуально ", C26), 0) > 0, 0, )) | F26: 3 | G26: Подведение итогов в подразделении актуально, поставлены конкретные задачи и проводится в установленное время
F27: 0 | G27: Подведение итогов в подразделении не актуально, не поставлены задачи или не проводится
A28: 9. | B28: Несение службы наряда, назначенного от подразделения | C28: Отсутствуют замечания у личного состава наряда, назначенного от подразделения, командир отделения за качество несения службы оценен не ниже «хорошо» | D28: =IF(IFERROR(SEARCH("Отсутствуют замечания ", C28), 0) > 0, 5, IF(IFERROR(SEARCH("Выявлено не более одного замечания ", C28), 0) > 0, 3, IF(IFERROR(SEARCH("Отстранен от несения службы ", C28), 0) > 0, 0,))) | F28: 5 | G28: Отсутствуют замечания у личного состава наряда, назначенного от подразделения, командир отделения за качество несения службы оценен не ниже «хорошо»
F29: 3 | G29: Выявлено не более одного замечания у личного состава наряда, назначенного от подразделения, командир отделения за качество несения службы оценен не ниже «хорошо»
F30: 0 | G30: Отстранен от несения службы или выявлено более одного замечания у личного состава наряда, назначенного от подразделения, или командир отделения за качество несения службы оценен ниже «хорошо»
A31: 10. | B31: Соблюдение требований безопасности | C31: Отсутствуют нарушения ТБ, которые привели к травматизму личного состава в подразделении | D31: =IF(IFERROR(SEARCH("Отсутствуют нарушения ТБ", C31), 0) > 0, 10, IF(IFERROR(SEARCH("Имелись нарушения ТБ", C31), 0) > 0, 0, )) | F31: 10 | G31: Отсутствуют нарушения ТБ, которые привели к травматизму личного состава в подразделении
F32: 0 | G32: Имелись нарушения ТБ, которые привели к травматизму личного состава в подразделении
A33: 11. | B33: Соблюдение элементов распорядка дня | C33: Элементы распорядка дня соблюдаются | D33: =IF(IFERROR(SEARCH("Элементы распорядка дня соблюдаются", C33), 0) > 0, 10, IF(IFERROR(SEARCH("Допущено не более трех", C33), 0) > 0, 5, IF(IFERROR(SEARCH("Допущено более трёх нарушений ", C33), 0) > 0, 0,))) | F33: 10 | G33: Элементы распорядка дня соблюдаются
F34: 5 | G34: Допущено не более трех нарушений элементов распорядка дня, которые не привели к срыву мероприятия в целом
F35: 0 | G35: Допущено более трёх нарушений элементов распорядка дня, которые не привели к срыву мероприятия в целом, или допущен срыв, или нарушение командиром отделения
A36: 12. | B36: Состояние материальных средств (в том числе оружия) | C36: Материальные средства подразделения в наличии, исправны, обслужены, хранятся правильно | D36: =IF(IFERROR(SEARCH("Материальные средства ", C36), 0) > 0, 5, IF(IFERROR(SEARCH("Не выполнены ", C36), 0) > 0, 0, )) | F36: 5 | G36: Материальные средства подразделения в наличии, исправны, обслужены, хранятся правильно
F37: 0 | G37: Не выполнены критерии
A38: 13. | B38: Успеваемость по физической подготовке (культуре) командира отделения (по итогам промежуточной аттестации) | C38: Оценка по физической подготовке (культуре) 5 | D38: =IF(IFERROR(SEARCH("5", C38), 0) > 0, 2, IF(IFERROR(SEARCH("4", C38), 0) > 0, 1, )) | F38: 2 | G38: Оценка по физической подготовке (культуре) 5
F39: 1 | G39: Оценка по физической подготовке (культуре) 4
A40: Итоговая сумма баллов: | D40: =SUM(D7:D39)
A43: Начальник курса
...

Sheet ЗКВ-412
A1: ВЕДОМОСТЬ
A2: индивидуальной оценки
A3: заместителя командира взвода 412 учебной группы сержанта Дворянова Дмитрия Андреевича
A5: № | B5: Оценка служебной деятельности | C5: Результаты служебной деятельности | D5: Количество баллов
A6: п/п
A7: 1. | B7: Результаты промежуточной аттестации | D7: =IF(IFERROR(SEARCH("подразделения ≥ 4,5", C7), 0) > 0, 5, IF(IFERROR(SEARCH("подразделения ≥ 4,0", C7), 0) > 0, 3, IF(IFERROR(SEARCH("<", C7), 0) > 0, 0,))) | G7: Средний балл подразделения ≥ 4,5 Средний балл ЗКВ ≥ 4,0
G8: Средний балл подразделения ≥ 4,0 Средний балл ЗКВ ≥ 4,0
G9: Средний балл подразделения < 4,0 Средний балл ЗКВ < 4,0
A10: 2. | B10: Наличие академических задолженностей | D10: =IF(C10="Академические задолженности отсутствуют",10,IF(C10="Имеются академические задолженности в учебной группе или у ЗКВ",0,"")) | G10: Академические задолженности отсутствуют
G11: Имеются академические задолженности в учебной группе или у ЗКВ
A12: 3. | B12: Наличие текущих задолженностей | D12: =IF(C12="В подразделении и у ЗКВ отсутствуют текущие задолженности",5,IF(C12="Имеются менее 20% текущих задолженностей в подразделении или у ЗКВ",3,IF(C12="Имеются более 20% текущих задолженностей в подразделении или у ЗКВ",0,""))) | G12: В подразделении и у ЗКВ отсутствуют текущие задолженности
G13: Имеются менее 20% текущих задолженностей в подразделении или у ЗКВ
G14: Имеются более 20% текущих задолженностей в подразделении или у ЗКВ
A15: 4. | B15: Организация учебных занятий | D15: =IF(C15="Подразделение прибыло на занятие своевременно; дежурный по аудитории назначен; ЖУУЗ и классная доска оформлены; литература, конспекты, ПЭВМ (по необходимости) получены; внутренний порядок в аудитории поддерживается",5,IF(C15="Подразделение прибыло на занятие своевременно; дежурный по аудитории назначен; литература, конспекты, ПЭВМ (по необходимости) получены; ЖУУЗ или классная доска оформлены не своевременно; или имеются отклонения по внутреннему порядку в аудитории",3,IF(C15="Подразделение опоздало на занятие; или ЖУУЗ и классная доска не оформлены; литература, конспекты, ПЭВМ (по необходимости) не получены; или внутренний порядок в аудитории не поддерживается",0,""))) | L15: Подразделение прибыло на занятие своевременно; дежурный по аудитории назначен; ЖУУЗ и классная доска оформлены; литература, конспекты, ПЭВМ (по необходимости) получены; внутренний порядок в аудитории поддерживается
L16: Подразделение прибыло на занятие своевременно; дежурный по аудитории назначен; литература, конспекты, ПЭВМ (по необходимости) получены; ЖУУЗ или классная доска оформлены не своевременно; или имеются отклонения по внутреннему порядку в аудитории
L17: Подразделение опоздало на занятие; или ЖУУЗ и классная доска не оформлены; литература, конспекты, ПЭВМ (по необходимости) не получены; или внутренний порядок в аудитории не поддерживается
A18: 5. | B18: Организация самостоятельной работы | D18: =IF(IFERROR(SEARCH("30%", C18), 0) > 0, 5, IF(IFERROR(SEARCH("10%", C18), 0) > 0, 3, IF(IFERROR(SEARCH("не получены", C18), 0) > 0, 0,))) | L18: Подразделение прибыло на СР своевременно; дежурный по аудитории назначен; ЖУУЗ и классная доска оформлены; внутренний порядок в аудитории поддерживается; литература, ПЭВМ (не менее 30%) получены; журнал ЗКВ, план СР оформлены и выполняются; перерывы организованы
L19: Подразделение прибыло на СР своевременно; дежурный по аудитории назначен; ЖУУЗ или классная доска заполнены не своевременно; имеются отклонения по внутреннему порядку в аудитории; ПЭВМ (не менее 10%) получены; литература получена в недостаточном количестве; журнал ЗКВ, план СР оформлены не в полном объеме или не выполняется; перерывы организованы
L20: Подразделение опоздала на СР; или дежурный по аудитории не назначен; или ЖУУЗ и классная доска не оформлены; или внутренний порядок в аудитории не поддерживается; или литература, ПЭВМ не получены; или журнал ЗКВ, план СР не оформлены и не выполняются; или личный состав спит; или перерывы не организованы
A21: 6. | B21: Замечания от УМО, преподавателей и старших начальников в ходе проведения занятий и самостоятельной работы | D21: =IF(C21="Замечания в подразделении и у ЗКВ отсутствуют",5,IF(C21="В подразделении 2 замечания у ЗКВ отсутствуют",3,IF(C21="В подразделении 3 и более замечаний или замечания у ЗКВ",0,""))) | G21: Замечания в подразделении и у ЗКВ отсутствуют
G22: В подразделении 2 замечания у ЗКВ отсутствуют
G23: В подразделении 3 и более замечаний или замечания у ЗКВ
A24: 7. | B24: Наличие ПРО, ПРЕ, грубых дисциплинарных проступков | D24: =IF(C24="ПРО, ПРЕ, ГДП в подразделении и ЗКВ отсутствуют",10,IF(C24="ПРО, ПРЕ отсутствуют, имеются не снятые взыскания за ГДП в подразделении, у ЗКВ отсутствуют",2,IF(C24="Совершено ПРО, ПРЕ, ГДП в подразделении или ЗКВ или допущено сокрытие",0,""))) | G24: ПРО, ПРЕ, ГДП в подразделении и ЗКВ отсутствуют
G25: ПРО, ПРЕ отсутствуют, имеются не снятые взыскания за ГДП в подразделении, у ЗКВ отсутствуют
G26: Совершено ПРО, ПРЕ, ГДП в подразделении или ЗКВ или допущено сокрытие
A27: 8. | B27: Дисциплинарная практика | D27: =IF(C27="Дисциплинарная практика к подчиненному личному составу ведется",5,IF(C27="Дисциплинарная практика к подчиненному личному составу не реализуется или ЗКВ имеет дисциплинарные взыскания",0,"")) | G27: Дисциплинарная практика к подчиненному личному составу ведется
G28: Дисциплинарная практика к подчиненному личному составу не реализуется или ЗКВ имеет дисциплинарные взыскания
A29: 9. | B29: Знание обстановки в подразделении с докладом начальнику факультета (курса) по возможным отклонениям, ведение книжки сержанта | D29: =IF(C29="Обстановкой владеет, доклады представляет, книжка сержантов актуальна",10,IF(C29="Обстановкой владеет, доклады представляет, книжка сержантов не актуальна",5,IF(C29="Обстановкой не владеет, доклады не представляет, книжка сержантов не актуальна",0,""))) | G29: Обстановкой владеет, доклады представляет, книжка сержантов актуальна
G30: Обстановкой владеет, доклады представляет, книжка сержантов не актуальна
G31: Обстановкой не владеет, доклады не представляет, книжка сержантов не актуальна
A32: 10. | B32: Подведение итогов в подразделении | D32: =IF(C32="Подведение итогов актуально, поставлены конкретные задачи и проводится в установленное время",3,IF(C32="Подведение итогов не актуально, не поставлены задачи или не проводится",0,"")) | G32: Подведение итогов актуально, поставлены конкретные задачи и проводится в установленное время
G33: Подведение итогов не актуально, не поставлены задачи или не проводится
A34: 11. | B34: Распределение увольнений | D34: =IF(C34="Увольнения распределены равномерно",2,IF(C34="Увольнения распределяются не равномерно",0,"")) | G34: Увольнения распределены равномерно
G35: Увольнения распределяются не равномерно
A36: 12. | B36: Распределение нарядов, уборщиков по территории и расположению | D36: =IF(C36="Наряды и уборщики распределены равномерно",2,IF(C36="Наряды распределены равномерно, уборщики не равномерно",1,IF(C36="Наряды и уборщики распределены не равномерно",0,""))) | G36: Наряды и уборщики распределены равномерно
G37: Наряды распределены равномерно, уборщики не равномерно
G38: Наряды и уборщики распределены не равномерно
A39: 13. | B39: Несение службы наряда, назначенного от подразделения | D39: =IF(C39="Замечания у подчиненного л/с отсутствуют, ЗКВ оценен не ниже «хорошо»",5,IF(C39="Выявлено не более 2 замечаний у подчиненного л/с, ЗКВ оценен не ниже «хорошо»",3,IF(C39="Л/с отстранен или выявлено более 2 замечаний, ЗКВ оценен ниже «хорошо»",0,""))) | G39: Замечания у подчиненного л/с отсутствуют, ЗКВ оценен не ниже «хорошо»
G40: Выявлено не более 2 замечаний у подчиненного л/с, ЗКВ оценен не ниже «хорошо»
G41: Л/с отстранен или выявлено более 2 замечаний, ЗКВ оценен ниже «хорошо»
...

Sheet КО1-412
A1: ВЕДОМОСТЬ
A2: индивидуальной оценки
A3: командира 1-ого отделения 412 учебной группы младшего сержанта Мещерякова Степана Владимировича
A5: № | B5: Оценка служебной деятельности | C5: Результаты служебной деятельности | D5: Количество баллов
A6: п/п
A7: 1. | B7: Результаты промежуточной аттестации | C7: Средний балл подразделения ≥ 4,0 Средний балл командира отделения ≥ 4,0 | D7: =IF(IFERROR(SEARCH("подразделения ≥ 4,5", C7), 0) > 0, 5, IF(IFERROR(SEARCH("подразделения ≥ 4,0", C7), 0) > 0, 3, IF(IFERROR(SEARCH("<", C7), 0) > 0, 0,))) | F7: 5 | G7: Средний балл подразделения ≥ 4,5 Средний балл командира отделения ≥ 4,0
F8: 3 | G8: Средний балл подразделения ≥ 4,0 Средний балл командира отделения ≥ 4,0
F9: 0 | G9: Средний балл подразделения < 4,0 Средний балл командира отделения < 4,0
A10: 2. | B10: Наличие академических задолженностей | C10: Академические задолженности в подразделении и у командира учебной группы отсутствуют | D10: =IF(IFERROR(SEARCH("отсутствуют", C10), 0) > 0, 10, IF(IFERROR(SEARCH("имеются", C10), 0) > 0, 0, )) | F10: 10 | G10: Академические задолженности в подразделении и у командира учебной группы отсутствуют
F11: 0 | G11: Академические задолженности в подразделении или у командира учебной группы имеются
A12: 3. | B12: Наличие текущих задолженностей | C12: Текущие задолженности в подразделении и у командира учебной группы отсутствуют | D12: =IF(IFERROR(SEARCH("Текущие задолженности в подразделении и у командира учебной группы отсутствуют", C12), 0) > 0, 5, IF(IFERROR(SEARCH("менее 20%", C12), 0) > 0, 3, IF(IFERROR(SEARCH("более 20%", C12), 0) > 0, 0,))) | F12: 5 | G12: Текущие задолженности в подразделении и у командира учебной группы отсутствуют
F13: 3 | G13: Текущие задолженности в подразделении менее 20% и у командира учебной группы отсутствуют
F14: 0 | G14: Текущие задолженности в подразделении более 20% или имеется у командира учебной группы
A15: 4. | B15: Замечания от УМО, преподавателей и старших начальников в ходе проведения занятий и самостоятельной работы | C15: Наличие одного замечания в подразделении и отсутствует у командира отделения | D15: =IF(IFERROR(SEARCH("Отсутствуют", C15), 0) > 0, 5, IF(IFERROR(SEARCH("Наличие одного", C15), 0) > 0, 3, IF(IFERROR(SEARCH("Наличие двух", C15), 0) > 0, 0,))) | F15: 5 | G15: Отсутствуют замечания в подразделении или у командира отделения
F16: 3 | G16: Наличие одного замечания в подразделении и отсутствует у командира отделения
F17: 0 | G17: Наличие двух и более замечаний в подразделении или у командира отделения
A18: 5. | B18: Наличие ПРО, ПРЕ, грубых дисциплинарных проступков | C18: ПРО, ПРЕ, ГДП в подразделении и у командира отделения отсутствуют | D18: =IF(IFERROR(SEARCH("ПРО, ПРЕ, ГДП в подразделении и у командира отделения отсутствуют", C18), 0) > 0, 10, IF(IFERROR(SEARCH("имеются не снятые взыскания ", C18), 0) > 0, 2, IF(IFERROR(SEARCH("допущено сокрытие", C18), 0) > 0, 0,))) | F18: 10 | G18: ПРО, ПРЕ, ГДП в подразделении и у командира отделения отсутствуют
F19: 2 | G19: ПРО, ПРЕ отсутствуют, имеются не снятые взыскания за ГДП в подразделении, у командира отделения отсутствуют
F20: 0 | G20: Совершено ПРО, ПРЕ, ГДП в подразделении или командиром отделения, или допущено сокрытие
A21: 6. | B21: Дисциплинарная практика | C21: Реализует дисциплинарную практику к подчинённому личному составу и не имеет дисциплинарных взысканий | D21: =IF(IFERROR(SEARCH("Реализует дисциплинарную практику к подчинённому личному составу и не имеет дисциплинарных взысканий", C21), 0) > 0, 5, IF(IFERROR(SEARCH("Не реализует ", C21), 0) > 0, 0, )) | F21: 5 | G21: Реализует дисциплинарную практику к подчинённому личному составу и не имеет дисциплинарных взысканий
F22: 0 | G22: Не реализует дисциплинарную практику к подчинённому личному составу или имеет дисциплинарные взыскания
A23: 7. | B23: Знание обстановки в подразделении с докладом начальнику факультета (курса) по возможным отклонениям, ведение книжки сержанта | C23: Обстановку в подразделении знает и докладывает НФ (НК), информация в книжке сержанта актуальная | D23: =IF(IFERROR(SEARCH("сержанта актуальная", C23), 0) > 0, 10, IF(IFERROR(SEARCH("информация в книжке сержанта не актуальная", C23), 0) > 0, 5, IF(IFERROR(SEARCH("не представлен; и информация в книжке сержанта не актуальная", C23), 0) > 0, 0,))) | F23: 10 | G23: Обстановку в подразделении знает и докладывает НФ (НК), информация в книжке сержанта актуальная
F24: 5 | G24: Обстановку в подразделении знает и докладывает НФ (НК), информация в книжке сержанта не актуальная
F25: 0 | G25: Обстановкой в подразделении не владеет, или доклад НФ (НК) не представлен; и информация в книжке сержанта не актуальная
A26: 8. | B26: Подведение итогов в подразделении | C26: Подведение итогов в подразделении актуально, поставлены конкретные задачи и проводится в установленное время | D26: =IF(IFERROR(SEARCH("Подведение итогов в подразделении актуально", C26), 0) > 0, 3, IF(IFERROR(SEARCH("Подведение итогов в подразделении не актуально ", C26), 0) > 0, 0, )) | F26: 3 | G26: Подведение итогов в подразделении актуально, поставлены конкретные задачи и проводится в установленное время
F27: 0 | G27: Подведение итогов в подразделении не актуально, не поставлены задачи или не проводится
A28: 9. | B28: Несение службы наряда, назначенного от подразделения | C28: Отсутствуют замечания у личного состава наряда, назначенного от подразделения, командир отделения за качество несения службы оценен не ниже «хорошо» | D28: =IF(IFERROR(SEARCH("Отсутствуют замечания ", C28), 0) > 0, 5, IF(IFERROR(SEARCH("Выявлено не более одного замечания ", C28), 0) > 0, 3, IF(IFERROR(SEARCH("Отстранен от несения службы ", C28), 0) > 0, 0,))) | F28: 5 | G28: Отсутствуют замечания у личного состава наряда, назначенного от подразделения, командир отделения за качество несения службы оценен не ниже «хорошо»
F29: 3 | G29: Выявлено не более одного замечания у личного состава наряда, назначенного от подразделения, командир отделения за качество несения службы оценен не ниже «хорошо»
F30: 0 | G30: Отстранен от несения службы или выявлено более одного замечания у личного состава наряда, назначенного от подразделения, или командир отделения за качество несения службы оценен ниже «хорошо»
A31: 10. | B31: Соблюдение требований безопасности | C31: Отсутствуют нарушения ТБ, которые привели к травматизму личного состава в подразделении | D31: =IF(IFERROR(SEARCH("Отсутствуют нарушения ТБ", C31), 0) > 0, 10, IF(IFERROR(SEARCH("Имелись нарушения ТБ", C31), 0) > 0, 0, )) | F31: 10 | G31: Отсутствуют нарушения ТБ, которые привели к травматизму личного состава в подразделении
F32: 0 | G32: Имелись нарушения ТБ, которые привели к травматизму личного состава в подразделении
A33: 11. | B33: Соблюдение элементов распорядка дня | C33: Элементы распорядка дня соблюдаются | D33: =IF(IFERROR(SEARCH("Элементы распорядка дня соблюдаются", C33), 0) > 0, 10, IF(IFERROR(SEARCH("Допущено не более трех", C33), 0) > 0, 5, IF(IFERROR(SEARCH("Допущено более трёх нарушений ", C33), 0) > 0, 0,))) | F33: 10 | G33: Элементы распорядка дня соблюдаются
F34: 5 | G34: Допущено не более трех нарушений элементов распорядка дня, которые не привели к срыву мероприятия в целом
F35: 0 | G35: Допущено более трёх нарушений элементов распорядка дня, которые не привели к срыву мероприятия в целом, или допущен срыв, или нарушение командиром отделения
A36: 12. | B36: Состояние материальных средств (в том числе оружия) | C36: Материальные средства подразделения в наличии, исправны, обслужены, хранятся правильно | D36: =IF(IFERROR(SEARCH("Материальные средства ", C36), 0) > 0, 5, IF(IFERROR(SEARCH("Не выполнены ", C36), 0) > 0, 0, )) | F36: 5 | G36: Материальные средства подразделения в наличии, исправны, обслужены, хранятся правильно
F37: 0 | G37: Не выполнены критерии
A38: 13. | B38: Успеваемость по физической подготовке (культуре) командира отделения (по итогам промежуточной аттестации) | C38: Оценка по физической подготовке (культуре) 5 | D38: =IF(IFERROR(SEARCH("5", C38), 0) > 0, 2, IF(IFERROR(SEARCH("4", C38), 0) > 0, 1, )) | F38: 2 | G38: Оценка по физической подготовке (культуре) 5
F39: 1 | G39: Оценка по физической подготовке (культуре) 4
A40: Итоговая сумма баллов: | D40: =SUM(D7:D39)
A43: Начальник курса
...

Sheet КО2-412
A1: ВЕДОМОСТЬ
A2: индивидуальной оценки
A3: командира 2-ого отделения 412 учебной группы рядового Шкрядо Андрея Сергеевича
A5: № | B5: Оценка служебной деятельности | C5: Результаты служебной деятельности | D5: Количество баллов
A6: п/п
A7: 1. | B7: Результаты промежуточной аттестации | C7: Средний балл подразделения ≥ 4,0 Средний балл командира отделения ≥ 4,0 | D7: =IF(IFERROR(SEARCH("подразделения ≥ 4,5", C7), 0) > 0, 5, IF(IFERROR(SEARCH("подразделения ≥ 4,0", C7), 0) > 0, 3, IF(IFERROR(SEARCH("<", C7), 0) > 0, 0,))) | F7: 5 | G7: Средний балл подразделения ≥ 4,5 Средний балл командира отделения ≥ 4,0
F8: 3 | G8: Средний балл подразделения ≥ 4,0 Средний балл командира отделения ≥ 4,0
F9: 0 | G9: Средний балл подразделения < 4,0 Средний балл командира отделения < 4,0
A10: 2. | B10: Наличие академических задолженностей | C10: Академические задолженности в подразделении и у командира учебной группы отсутствуют | D10: =IF(IFERROR(SEARCH("отсутствуют", C10), 0) > 0, 10, IF(IFERROR(SEARCH("имеются", C10), 0) > 0, 0, )) | F10: 10 | G10: Академические задолженности в подразделении и у командира учебной группы отсутствуют
F11: 0 | G11: Академические задолженности в подразделении или у командира учебной группы имеются
A12: 3. | B12: Наличие текущих задолженностей | C12: Текущие задолженности в подразделении и у командира учебной группы отсутствуют | D12: =IF(IFERROR(SEARCH("Текущие задолженности в подразделении и у командира учебной группы отсутствуют", C12), 0) > 0, 5, IF(IFERROR(SEARCH("менее 20%", C12), 0) > 0, 3, IF(IFERROR(SEARCH("более 20%", C12), 0) > 0, 0,))) | F12: 5 | G12: Текущие задолженности в подразделении и у командира учебной группы отсутствуют
F13: 3 | G13: Текущие задолженности в подразделении менее 20% и у командира учебной группы отсутствуют
F14: 0 | G14: Текущие задолженности в подразделении более 20% или имеется у командира учебной группы
A15: 4. | B15: Замечания от УМО, преподавателей и старших начальников в ходе проведения занятий и самостоятельной работы | C15: Наличие одного замечания в подразделении и отсутствует у командира отделения | D15: =IF(IFERROR(SEARCH("Отсутствуют", C15), 0) > 0, 5, IF(IFERROR(SEARCH("Наличие одного", C15), 0) > 0, 3, IF(IFERROR(SEARCH("Наличие двух", C15), 0) > 0, 0,))) | F15: 5 | G15: Отсутствуют замечания в подразделении или у командира отделения
F16: 3 | G16: Наличие одного замечания в подразделении и отсутствует у командира отделения
F17: 0 | G17: Наличие двух и более замечаний в подразделении или у командира отделения
A18: 5. | B18: Наличие ПРО, ПРЕ, грубых дисциплинарных проступков | C18: ПРО, ПРЕ, ГДП в подразделении и у командира отделения отсутствуют | D18: =IF(IFERROR(SEARCH("ПРО, ПРЕ, ГДП в подразделении и у командира отделения отсутствуют", C18), 0) > 0, 10, IF(IFERROR(SEARCH("имеются не снятые взыскания ", C18), 0) > 0, 2, IF(IFERROR(SEARCH("допущено сокрытие", C18), 0) > 0, 0,))) | F18: 10 | G18: ПРО, ПРЕ, ГДП в подразделении и у командира отделения отсутствуют
F19: 2 | G19: ПРО, ПРЕ отсутствуют, имеются не снятые взыскания за ГДП в подразделении, у командира отделения отсутствуют
F20: 0 | G20: Совершено ПРО, ПРЕ, ГДП в подразделении или командиром отделения, или допущено сокрытие
A21: 6. | B21: Дисциплинарная практика | C21: Реализует дисциплинарную практику к подчинённому личному составу и не имеет дисциплинарных взысканий | D21: =IF(IFERROR(SEARCH("Реализует дисциплинарную практику к подчинённому личному составу и не имеет дисциплинарных взысканий", C21), 0) > 0, 5, IF(IFERROR(SEARCH("Не реализует ", C21), 0) > 0, 0, )) | F21: 5 | G21: Реализует дисциплинарную практику к подчинённому личному составу и не имеет дисциплинарных взысканий
F22: 0 | G22: Не реализует дисциплинарную практику к подчинённому личному составу или имеет дисциплинарные взыскания
A23: 7. | B23: Знание обстановки в подразделении с докладом начальнику факультета (курса) по возможным отклонениям, ведение книжки сержанта | C23: Обстановку в подразделении знает и докладывает НФ (НК), информация в книжке сержанта актуальная | D23: =IF(IFERROR(SEARCH("сержанта актуальная", C23), 0) > 0, 10, IF(IFERROR(SEARCH("информация в книжке сержанта не актуальная", C23), 0) > 0, 5, IF(IFERROR(SEARCH("не представлен; и информация в книжке сержанта не актуальная", C23), 0) > 0, 0,))) | F23: 10 | G23: Обстановку в подразделении знает и докладывает НФ (НК), информация в книжке сержанта актуальная
F24: 5 | G24: Обстановку в подразделении знает и докладывает НФ (НК), информация в книжке сержанта не актуальная
F25: 0 | G25: Обстановкой в подразделении не владеет, или доклад НФ (НК) не представлен; и информация в книжке сержанта не актуальная
A26: 8. | B26: Подведение итогов в подразделении | C26: Подведение итогов в подразделении актуально, поставлены конкретные задачи и проводится в установленное время | D26: =IF(IFERROR(SEARCH("Подведение итогов в подразделении актуально", C26), 0) > 0, 3, IF(IFERROR(SEARCH("Подведение итогов в подразделении не актуально ", C26), 0) > 0, 0, )) | F26: 3 | G26: Подведение итогов в подразделении актуально, поставлены конкретные задачи и проводится в установленное время
